Workbook

Sheet 2026 전학년
A1: 2026학년도 당해년도 전 학년(1, 2, 3학년) 교육과정 편성표
A2: 웅상고등학교(공립)
A3: 구분 | B3: 교과(군) | C3: 과목 유형 | D3: 과목 | E3: 기본 학점 | F3: 운영 학점 | G3: 1학년 | I3: 2학년 | K3: 3학년 | M3: 개설 여부 | O3: 성적처리 유형
G4: 1학기 | H4: 2학기 | I4: 1학기 | J4: 2학기 | K4: 1학기 | L4: 2학기 | M4: 1학기 | N4: 2학기
A5: 학 교 지 정 과 목 | B5: 국어 | C5: 공통 | D5: 공통국어1 | E5: 4 | F5: 4 | G5: 4 | M5: O | N5: X | O5: 성취도 5단계+석차등급O
C6: 공통 | D6: 공통국어2 | E6: 4 | F6: 4 | H6: 4 | M6: X | N6: O | O6: 성취도 5단계+석차등급O
C7: 일반 | D7: 독서와 작문 | E7: 5 | F7: 4 | I7: 4 | M7: O | N7: X | O7: 성취도 5단계+석차등급O
C8: 일반 | D8: 문학 | E8: 5 | F8: 4 | J8: 4 | M8: X | N8: O | O8: 성취도 5단계+석차등급O
B9: 수학 | C9: 공통 | D9: 공통수학1 | E9: 4 | F9: 4 | G9: 4 | M9: O | N9: X | O9: 성취도 5단계+석차등급O
C10: 공통 | D10: 공통수학2 | E10: 4 | F10: 4 | H10: 4 | M10: X | N10: O | O10: 성취도 5단계+석차등급O
C11: 일반 | D11: 대수 | E11: 5 | F11: 4 | I11: 4 | M11: O | N11: X | O11: 성취도 5단계+석차등급O
C12: 일반 | D12: 미적분Ⅰ | E12: 5 | F12: 4 | J12: 4 | M12: X | N12: O | O12: 성취도 5단계+석차등급O
B13: 영어 | C13: 공통 | D13: 공통영어1 | E13: 4 | F13: 4 | G13: 4 | M13: O | N13: X | O13: 성취도 5단계+석차등급O
C14: 공통 | D14: 공통영어2 | E14: 4 | F14: 4 | H14: 4 | M14: X | N14: O | O14: 성취도 5단계+석차등급O
C15: 일반 | D15: 영어Ⅰ | E15: 5 | F15: 4 | I15: 4 | M15: O | N15: X | O15: 성취도 5단계+석차등급O
C16: 일반 | D16: 영어Ⅱ | E16: 5 | F16: 4 | J16: 4 | M16: X | N16: O | O16: 성취도 5단계+석차등급O
B17: 사회 | C17: 공통 | D17: 한국사1 | E17: 3 | F17: 3 | G17: 3 | M17: O | N17: X | O17: 성취도 5단계+석차등급O
C18: 공통 | D18: 한국사2 | E18: 3 | F18: 3 | H18: 3 | M18: X | N18: O | O18: 성취도 5단계+석차등급O
C19: 공통 | D19: 통합사회1 | E19: 4 | F19: 4 | G19: 4 | M19: O | N19: X | O19: 성취도 5단계+석차등급O
C20: 공통 | D20: 통합사회2 | E20: 4 | F20: 4 | H20: 4 | M20: X | N20: O | O20: 성취도 5단계+석차등급O
B21: 과학 | C21: 공통 | D21: 통합과학1 | E21: 4 | F21: 4 | G21: 4 | M21: O | N21: X | O21: 성취도 5단계+석차등급O
C22: 공통 | D22: 통합과학2 | E22: 4 | F22: 4 | H22: 4 | M22: X | N22: O | O22: 성취도 5단계+석차등급O
C23: 공통 | D23: 과학탐구실험1 | E23: 1 | F23: 1 | G23: 1 | M23: O | N23: X | O23: 성취도 3단계
C24: 공통 | D24: 과학탐구실험2 | E24: 1 | F24: 1 | H24: 1 | M24: X | N24: O | O24: 성취도 3단계
B25: 체육 | C25: 일반 | D25: 체육1 | E25: 3 | F25: 2 | G25: 2 | M25: O | N25: X | O25: 성취도 3단계
C26: 일반 | D26: 체육2 | E26: 3 | F26: 2 | H26: 2 | M26: X | N26: O | O26: 성취도 3단계
C27: 진로 | D27: 스포츠 과학 | E27: 2 | F27: 1 | I27: 1 | M27: O | N27: X | O27: 성취도 3단계
C28: 진로 | D28: 스포츠 문화 | E28: 2 | F28: 1 | J28: 1 | M28: X | N28: O | O28: 성취도 3단계
C29: 일반 | D29: 운동과 건강 | E29: 5 | F29: 4 | K29: 2 | L29: 2 | M29: O | N29: O | O29: 성취도 3단계
B30: 예술 | C30: 일반 | D30: 음악↔미술 | E30: 3 | F30: 2 | I30: 2 | J30: 2 | M30: O | N30: O | O30: 성취도 3단계
C31: 일반 | M31: O | N31: O | O31: 성취도 3단계
B32: 기술·가정 | C32: 일반 | D32: 기술·가정↔정보 | E32: 4 | F32: 3 | G32: 3 | H32: 3 | M32: O | N32: O | O32: 성취도 5단계+석차등급O
C33: 일반 | M33: O | N33: O | O33: 성취도 5단계+석차등급O
G34: =SUM(G5:G33) -> 29 | H34: =SUM(H5:H33) -> 29 | I34: =SUM(I5:I33) -> 15 | J34: =SUM(J5:J33) -> 15 | K34: =SUM(K5:K33) -> 2 | L34: =SUM(L5:L33) -> 2
A35: 선택군 A | B35: 사회 | C35: 진로 | D35: 윤리와 사상 | E35: 4 | F35: 4 | I35: 4 | M35: O | N35: X | O35: 성취도 5단계+석차등급O
C36: 일반 | D36: 사회와 문화 | E36: 4 | F36: 4 | I36: 4 | M36: O | N36: X | O36: 성취도 5단계+석차등급O
C37: 진로 | D37: 동아시아 역사 기행 | E37: 4 | F37: 4 | I37: 4 | M37: O | N37: X | O37: 성취도 5단계+석차등급O
C38: 융합 | D38: 여행지리 | E38: 4 | F38: 4 | M38: O | N38: X | O38: 성취도 5단계+석차등급X
C39: 진로 | D39: 도시의 미래 탐구 | E39: 4 | F39: 4 | M39: O | N39: X | O39: 성취도 5단계+석차등급O
B40: 과학 | C40: 일반 | D40: 물리학 | E40: 4 | F40: 4 | M40: O | N40: X | O40: 성취도 5단계+석차등급O
...

Sheet 2026 입학생 3개년(1학년)
A1: 2026학년도 입학생 3개년 교육과정 편성표(1학년) | Q1: Ⅰ | R1: Ⅱ
A2: 웅상고등학교(공립)
A3: 구분 | B3: 교과(군) | C3: 과목 유형 | D3: 과목 | E3: 기본 학점 | F3: 운영 학점 | G3: 1학년 | I3: 2학년 | K3: 3학년 | M3: 편성학점 합 | O3: 성적처리 유형
G4: 1학기 | H4: 2학기 | I4: 1학기 | J4: 2학기 | K4: 1학기 | L4: 2학기 | M4: 교과(군) | N4: 선택군
A5: 학 교 지 정 과 목 | B5: 국어 | C5: =VLOOKUP(D5,숨김!$B$3:$E$300,2,0) -> 공통 | D5: 공통국어1 | E5: =VLOOKUP(D5,숨김!$B$3:$E$300,3,0) -> 4 | F5: 4 | G5: 4 | M5: =SUM(G5:L9) -> 20 | N5: =SUM(M5,M10,M15) -> 60 | O5: =VLOOKUP(D5,숨김!$B$3:$E$300,4,0) -> 성취도 5단계+석차등급O
C6: =VLOOKUP(D6,숨김!$B$3:$E$300,2,0) -> 공통 | D6: 공통국어2 | E6: =VLOOKUP(D6,숨김!$B$3:$E$300,3,0) -> 4 | F6: 4 | H6: 4 | O6: =VLOOKUP(D6,숨김!$B$3:$E$300,4,0) -> 성취도 5단계+석차등급O
C7: =VLOOKUP(D7,숨김!$B$3:$E$300,2,0) -> 일반 | D7: 독서와 작문 | E7: =VLOOKUP(D7,숨김!$B$3:$E$300,3,0) -> 4 | F7: 4 | I7: 4 | O7: =VLOOKUP(D7,숨김!$B$3:$E$300,4,0) -> 성취도 5단계+석차등급O
C8: =VLOOKUP(D8,숨김!$B$3:$E$300,2,0) -> 일반 | D8: 문학 | E8: =VLOOKUP(D8,숨김!$B$3:$E$300,3,0) -> 4 | F8: 4 | J8: 4 | O8: =VLOOKUP(D8,숨김!$B$3:$E$300,4,0) -> 성취도 5단계+석차등급O
C9: =VLOOKUP(D9,숨김!$B$3:$E$300,2,0) -> 일반 | D9: 화법과 언어 | E9: =VLOOKUP(D9,숨김!$B$3:$E$300,3,0) -> 4 | F9: 4 | K9: 4 | O9: =VLOOKUP(D9,숨김!$B$3:$E$300,4,0) -> 성취도 5단계+석차등급O
B10: 수학 | C10: =VLOOKUP(D10,숨김!$B$3:$E$300,2,0) -> 공통 | D10: 공통수학1 | E10: =VLOOKUP(D10,숨김!$B$3:$E$300,3,0) -> 4 | F10: 4 | G10: 4 | M10: =SUM(G10:L14) -> 20 | O10: =VLOOKUP(D10,숨김!$B$3:$E$300,4,0) -> 성취도 5단계+석차등급O
C11: =VLOOKUP(D11,숨김!$B$3:$E$300,2,0) -> 공통 | D11: 공통수학2 | E11: =VLOOKUP(D11,숨김!$B$3:$E$300,3,0) -> 4 | F11: 4 | H11: 4 | O11: =VLOOKUP(D11,숨김!$B$3:$E$300,4,0) -> 성취도 5단계+석차등급O
C12: =VLOOKUP(D12,숨김!$B$3:$E$300,2,0) -> 일반 | D12: 대수 | E12: =VLOOKUP(D12,숨김!$B$3:$E$300,3,0) -> 4 | F12: 4 | I12: 4 | O12: =VLOOKUP(D12,숨김!$B$3:$E$300,4,0) -> 성취도 5단계+석차등급O
C13: =VLOOKUP(D13,숨김!$B$3:$E$300,2,0) -> 일반 | D13: 미적분Ⅰ | E13: =VLOOKUP(D13,숨김!$B$3:$E$300,3,0) -> 4 | F13: 4 | J13: 4 | O13: =VLOOKUP(D13,숨김!$B$3:$E$300,4,0) -> 성취도 5단계+석차등급O
C14: =VLOOKUP(D14,숨김!$B$3:$E$300,2,0) -> 일반 | D14: 확률과 통계 | E14: =VLOOKUP(D14,숨김!$B$3:$E$300,3,0) -> 4 | F14: 4 | K14: 4 | O14: =VLOOKUP(D14,숨김!$B$3:$E$300,4,0) -> 성취도 5단계+석차등급O
B15: 영어 | C15: =VLOOKUP(D15,숨김!$B$3:$E$300,2,0) -> 공통 | D15: 공통영어1 | E15: =VLOOKUP(D15,숨김!$B$3:$E$300,3,0) -> 4 | F15: 4 | G15: 4 | M15: =SUM(G15:L19) -> 20 | O15: =VLOOKUP(D15,숨김!$B$3:$E$300,4,0) -> 성취도 5단계+석차등급O
C16: =VLOOKUP(D16,숨김!$B$3:$E$300,2,0) -> 공통 | D16: 공통영어2 | E16: =VLOOKUP(D16,숨김!$B$3:$E$300,3,0) -> 4 | F16: 4 | H16: 4 | O16: =VLOOKUP(D16,숨김!$B$3:$E$300,4,0) -> 성취도 5단계+석차등급O
C17: =VLOOKUP(D17,숨김!$B$3:$E$300,2,0) -> 일반 | D17: 영어Ⅰ | E17: =VLOOKUP(D17,숨김!$B$3:$E$300,3,0) -> 4 | F17: 4 | I17: 4 | O17: =VLOOKUP(D17,숨김!$B$3:$E$300,4,0) -> 성취도 5단계+석차등급O
C18: =VLOOKUP(D18,숨김!$B$3:$E$300,2,0) -> 일반 | D18: 영어Ⅱ | E18: =VLOOKUP(D18,숨김!$B$3:$E$300,3,0) -> 4 | F18: 4 | J18: 4 | O18: =VLOOKUP(D18,숨김!$B$3:$E$300,4,0) -> 성취도 5단계+석차등급O
C19: =VLOOKUP(D19,숨김!$B$3:$E$300,2,0) -> 일반 | D19: 영어 독해와 작문 | E19: =VLOOKUP(D19,숨김!$B$3:$E$300,3,0) -> 4 | F19: 4 | K19: 4 | O19: =VLOOKUP(D19,숨김!$B$3:$E$300,4,0) -> 성취도 5단계+석차등급O
B20: 사회 | C20: =VLOOKUP(D20,숨김!$B$3:$E$300,2,0) -> 공통 | D20: 한국사1 | E20: =VLOOKUP(D20,숨김!$B$3:$E$300,3,0) -> 3 | F20: 3 | G20: 3 | M20: =SUM(G20:L21) -> 6 | O20: =VLOOKUP(D20,숨김!$B$3:$E$300,4,0) -> 성취도 5단계+석차등급O
C21: =VLOOKUP(D21,숨김!$B$3:$E$300,2,0) -> 공통 | D21: 한국사2 | E21: =VLOOKUP(D21,숨김!$B$3:$E$300,3,0) -> 3 | F21: 3 | H21: 3 | O21: =VLOOKUP(D21,숨김!$B$3:$E$300,4,0) -> 성취도 5단계+석차등급O
C22: =VLOOKUP(D22,숨김!$B$3:$E$300,2,0) -> 공통 | D22: 통합사회1 | E22: =VLOOKUP(D22,숨김!$B$3:$E$300,3,0) -> 4 | F22: 4 | G22: 4 | M22: =SUM(G22:L23) -> 8 | O22: =VLOOKUP(D22,숨김!$B$3:$E$300,4,0) -> 성취도 5단계+석차등급O
C23: =VLOOKUP(D23,숨김!$B$3:$E$300,2,0) -> 공통 | D23: 통합사회2 | E23: =VLOOKUP(D23,숨김!$B$3:$E$300,3,0) -> 4 | F23: 4 | H23: 4 | O23: =VLOOKUP(D23,숨김!$B$3:$E$300,4,0) -> 성취도 5단계+석차등급O
B24: 과학 | C24: =VLOOKUP(D24,숨김!$B$3:$E$300,2,0) -> 공통 | D24: 통합과학1 | E24: =VLOOKUP(D24,숨김!$B$3:$E$300,3,0) -> 4 | F24: 4 | G24: 4 | M24: =SUM(G24:L27) -> 10 | O24: =VLOOKUP(D24,숨김!$B$3:$E$300,4,0) -> 성취도 5단계+석차등급O
C25: =VLOOKUP(D25,숨김!$B$3:$E$300,2,0) -> 공통 | D25: 통합과학2 | E25: =VLOOKUP(D25,숨김!$B$3:$E$300,3,0) -> 4 | F25: 4 | H25: 4 | O25: =VLOOKUP(D25,숨김!$B$3:$E$300,4,0) -> 성취도 5단계+석차등급O
C26: =VLOOKUP(D26,숨김!$B$3:$E$300,2,0) -> 공통 | D26: 과학탐구실험1 | E26: =VLOOKUP(D26,숨김!$B$3:$E$300,3,0) -> 1 | F26: 1 | G26: 1 | O26: =VLOOKUP(D26,숨김!$B$3:$E$300,4,0) -> 성취도 3단계
C27: =VLOOKUP(D27,숨김!$B$3:$E$300,2,0) -> 공통 | D27: 과학탐구실험2 | E27: =VLOOKUP(D27,숨김!$B$3:$E$300,3,0) -> 1 | F27: 1 | H27: 1 | O27: =VLOOKUP(D27,숨김!$B$3:$E$300,4,0) -> 성취도 3단계
B28: 체육 | C28: =VLOOKUP(D28,숨김!$B$3:$E$300,2,0) -> 일반 | D28: 체육1 | E28: =VLOOKUP(D28,숨김!$B$3:$E$300,3,0) -> 3 | F28: 2 | G28: 2 | M28: =SUM(G28:L33) -> 10 | O28: =VLOOKUP(D28,숨김!$B$3:$E$300,4,0) -> 성취도 3단계
C29: =VLOOKUP(D29,숨김!$B$3:$E$300,2,0) -> 일반 | D29: 체육2 | E29: =VLOOKUP(D29,숨김!$B$3:$E$300,3,0) -> 3 | F29: 2 | H29: 2 | O29: =VLOOKUP(D29,숨김!$B$3:$E$300,4,0) -> 성취도 3단계
C30: =VLOOKUP(D30,숨김!$B$3:$E$300,2,0) -> 진로 | D30: 스포츠 과학 | E30: =VLOOKUP(D30,숨김!$B$3:$E$300,3,0) -> 2 | F30: 1 | I30: 1 | O30: =VLOOKUP(D30,숨김!$B$3:$E$300,4,0) -> 성취도 3단계
C31: =VLOOKUP(D31,숨김!$B$3:$E$300,2,0) -> 진로 | D31: 스포츠 문화 | E31: =VLOOKUP(D31,숨김!$B$3:$E$300,3,0) -> 2 | F31: 1 | J31: 1 | O31: =VLOOKUP(D31,숨김!$B$3:$E$300,4,0) -> 성취도 3단계
C32: =VLOOKUP(D32,숨김!$B$3:$E$300,2,0) -> 융합 | D32: 스포츠 생활1 | E32: =VLOOKUP(D32,숨김!$B$3:$E$300,3,0) -> 3 | F32: 2 | K32: 2 | O32: =VLOOKUP(D32,숨김!$B$3:$E$300,4,0) -> 성취도 3단계
C33: =VLOOKUP(D33,숨김!$B$3:$E$300,2,0) -> 융합 | D33: 스포츠 생활2 | E33: =VLOOKUP(D33,숨김!$B$3:$E$300,3,0) -> 3 | F33: 2 | L33: 2 | O33: =VLOOKUP(D33,숨김!$B$3:$E$300,4,0) -> 성취도 3단계
B34: 예술 | C34: 일반 | D34: 음악↔미술 | E34: 3 | F34: 2↔2 | I34: 2 | J34: 2 | M34: =SUM(G34:L34) -> 4 | O34: 성취도 3단계
B35: 기술·가정 | C35: 일반 | D35: 기술·가정↔정보 | E35: 4 | F35: 3↔3 | G35: 3 | H35: 3 | M35: 6 | O35: 성취도 5단계+석차등급O
B36: 정보 | C36: 일반
A37: 학교 지정 과목 교과 이수 학점 소계 | G37: =SUM(G5:G36) -> 29 | H37: =SUM(H5:H36) -> 29 | I37: =SUM(I5:I36) -> 15 | J37: =SUM(J5:J36) -> 15 | K37: =SUM(K5:K36) -> 14 | L37: =SUM(L5:L36) -> 2 | M37: =SUM(G37:L37) -> 104
A38: 선택군A | B38: 사회 | C38: =VLOOKUP(D38,숨김!$B$3:$E$300,2,0) -> 진로 | D38: 윤리와 사상 | E38: =VLOOKUP(D38,숨김!$B$3:$E$300,3,0) -> 4 | F38: 4 | I38: 4 | M38: =SUM(G38:L46) -> 12 | O38: =VLOOKUP(D38,숨김!$B$3:$E$300,4,0) -> 성취도 5단계+석차등급O
C39: =VLOOKUP(D39,숨김!$B$3:$E$300,2,0) -> 일반 | D39: 사회와 문화 | E39: =VLOOKUP(D39,숨김!$B$3:$E$300,3,0) -> 4 | F39: 4 | I39: 4 | O39: =VLOOKUP(D39,숨김!$B$3:$E$300,4,0) -> 성취도 5단계+석차등급O
C40: =VLOOKUP(D40,숨김!$B$3:$E$300,2,0) -> 진로 | D40: 동아시아 역사 기행 | E40: =VLOOKUP(D40,숨김!$B$3:$E$300,3,0) -> 4 | F40: 4 | I40: 4 | O40: =VLOOKUP(D40,숨김!$B$3:$E$300,4,0) -> 성취도 5단계+석차등급O
...

Sheet 2026 입학생 3개년 변경후(1학년)
A1: 2026학년도 입학생 3개년 교육과정 편성표(1학년-변경후)
A2: 웅상고등학교(공립)
A3: 구분 | B3: 교과(군) | C3: 과목 유형 | D3: 과목 | E3: 기본 학점 | F3: 운영 학점 | G3: 1학년 | I3: 2학년 | K3: 3학년 | M3: 편성학점 합 | O3: 성적처리 유형
G4: 1학기 | H4: 2학기 | I4: 1학기 | J4: 2학기 | K4: 1학기 | L4: 2학기 | M4: 교과(군) | N4: 선택군
A5: 학 교 지 정 과 목 | B5: 국어 | C5: =VLOOKUP(D5,숨김!$B$3:$E$300,2,0) -> 공통 | D5: 공통국어1 | E5: =VLOOKUP(D5,숨김!$B$3:$E$300,3,0) -> 4 | F5: 4 | G5: 4 | M5: =SUM(G5:L9) -> 20 | N5: =SUM(M5,M10,M15) -> 60 | O5: =VLOOKUP(D5,숨김!$B$3:$E$300,4,0) -> 성취도 5단계+석차등급O
C6: =VLOOKUP(D6,숨김!$B$3:$E$300,2,0) -> 공통 | D6: 공통국어2 | E6: =VLOOKUP(D6,숨김!$B$3:$E$300,3,0) -> 4 | F6: 4 | H6: 4 | O6: =VLOOKUP(D6,숨김!$B$3:$E$300,4,0) -> 성취도 5단계+석차등급O
C7: =VLOOKUP(D7,숨김!$B$3:$E$300,2,0) -> 일반 | D7: 독서와 작문 | E7: =VLOOKUP(D7,숨김!$B$3:$E$300,3,0) -> 4 | F7: 4 | I7: 4 | O7: =VLOOKUP(D7,숨김!$B$3:$E$300,4,0) -> 성취도 5단계+석차등급O
C8: =VLOOKUP(D8,숨김!$B$3:$E$300,2,0) -> 일반 | D8: 문학 | E8: =VLOOKUP(D8,숨김!$B$3:$E$300,3,0) -> 4 | F8: 4 | J8: 4 | O8: =VLOOKUP(D8,숨김!$B$3:$E$300,4,0) -> 성취도 5단계+석차등급O
C9: =VLOOKUP(D9,숨김!$B$3:$E$300,2,0) -> 일반 | D9: 화법과 언어 | E9: =VLOOKUP(D9,숨김!$B$3:$E$300,3,0) -> 4 | F9: 4 | K9: 4 | O9: =VLOOKUP(D9,숨김!$B$3:$E$300,4,0) -> 성취도 5단계+석차등급O
B10: 수학 | C10: =VLOOKUP(D10,숨김!$B$3:$E$300,2,0) -> 공통 | D10: 공통수학1 | E10: =VLOOKUP(D10,숨김!$B$3:$E$300,3,0) -> 4 | F10: 4 | G10: 4 | M10: =SUM(G10:L14) -> 20 | O10: =VLOOKUP(D10,숨김!$B$3:$E$300,4,0) -> 성취도 5단계+석차등급O
C11: =VLOOKUP(D11,숨김!$B$3:$E$300,2,0) -> 공통 | D11: 공통수학2 | E11: =VLOOKUP(D11,숨김!$B$3:$E$300,3,0) -> 4 | F11: 4 | H11: 4 | O11: =VLOOKUP(D11,숨김!$B$3:$E$300,4,0) -> 성취도 5단계+석차등급O
C12: =VLOOKUP(D12,숨김!$B$3:$E$300,2,0) -> 일반 | D12: 대수 | E12: =VLOOKUP(D12,숨김!$B$3:$E$300,3,0) -> 4 | F12: 4 | I12: 4 | O12: =VLOOKUP(D12,숨김!$B$3:$E$300,4,0) -> 성취도 5단계+석차등급O
C13: =VLOOKUP(D13,숨김!$B$3:$E$300,2,0) -> 일반 | D13: 미적분Ⅰ | E13: =VLOOKUP(D13,숨김!$B$3:$E$300,3,0) -> 4 | F13: 4 | J13: 4 | O13: =VLOOKUP(D13,숨김!$B$3:$E$300,4,0) -> 성취도 5단계+석차등급O
C14: =VLOOKUP(D14,숨김!$B$3:$E$300,2,0) -> 일반 | D14: 확률과 통계 | E14: =VLOOKUP(D14,숨김!$B$3:$E$300,3,0) -> 4 | F14: 4 | K14: 4 | O14: =VLOOKUP(D14,숨김!$B$3:$E$300,4,0) -> 성취도 5단계+석차등급O
B15: 영어 | C15: =VLOOKUP(D15,숨김!$B$3:$E$300,2,0) -> 공통 | D15: 공통영어1 | E15: =VLOOKUP(D15,숨김!$B$3:$E$300,3,0) -> 4 | F15: 4 | G15: 4 | M15: =SUM(G15:L19) -> 20 | O15: =VLOOKUP(D15,숨김!$B$3:$E$300,4,0) -> 성취도 5단계+석차등급O
C16: =VLOOKUP(D16,숨김!$B$3:$E$300,2,0) -> 공통 | D16: 공통영어2 | E16: =VLOOKUP(D16,숨김!$B$3:$E$300,3,0) -> 4 | F16: 4 | H16: 4 | O16: =VLOOKUP(D16,숨김!$B$3:$E$300,4,0) -> 성취도 5단계+석차등급O
C17: =VLOOKUP(D17,숨김!$B$3:$E$300,2,0) -> 일반 | D17: 영어Ⅰ | E17: =VLOOKUP(D17,숨김!$B$3:$E$300,3,0) -> 4 | F17: 4 | I17: 4 | O17: =VLOOKUP(D17,숨김!$B$3:$E$300,4,0) -> 성취도 5단계+석차등급O
C18: =VLOOKUP(D18,숨김!$B$3:$E$300,2,0) -> 일반 | D18: 영어Ⅱ | E18: =VLOOKUP(D18,숨김!$B$3:$E$300,3,0) -> 4 | F18: 4 | J18: 4 | O18: =VLOOKUP(D18,숨김!$B$3:$E$300,4,0) -> 성취도 5단계+석차등급O
C19: =VLOOKUP(D19,숨김!$B$3:$E$300,2,0) -> 일반 | D19: 영어 독해와 작문 | E19: =VLOOKUP(D19,숨김!$B$3:$E$300,3,0) -> 4 | F19: 4 | K19: 4 | O19: =VLOOKUP(D19,숨김!$B$3:$E$300,4,0) -> 성취도 5단계+석차등급O
B20: 사회 | C20: =VLOOKUP(D20,숨김!$B$3:$E$300,2,0) -> 공통 | D20: 한국사1 | E20: =VLOOKUP(D20,숨김!$B$3:$E$300,3,0) -> 3 | F20: 3 | G20: 3 | M20: =SUM(G20:L21) -> 6 | O20: =VLOOKUP(D20,숨김!$B$3:$E$300,4,0) -> 성취도 5단계+석차등급O
C21: =VLOOKUP(D21,숨김!$B$3:$E$300,2,0) -> 공통 | D21: 한국사2 | E21: =VLOOKUP(D21,숨김!$B$3:$E$300,3,0) -> 3 | F21: 3 | H21: 3 | O21: =VLOOKUP(D21,숨김!$B$3:$E$300,4,0) -> 성취도 5단계+석차등급O
C22: =VLOOKUP(D22,숨김!$B$3:$E$300,2,0) -> 공통 | D22: 통합사회1 | E22: =VLOOKUP(D22,숨김!$B$3:$E$300,3,0) -> 4 | F22: 4 | G22: 4 | M22: =SUM(G22:L23) -> 8 | O22: =VLOOKUP(D22,숨김!$B$3:$E$300,4,0) -> 성취도 5단계+석차등급O
C23: =VLOOKUP(D23,숨김!$B$3:$E$300,2,0) -> 공통 | D23: 통합사회2 | E23: =VLOOKUP(D23,숨김!$B$3:$E$300,3,0) -> 4 | F23: 4 | H23: 4 | O23: =VLOOKUP(D23,숨김!$B$3:$E$300,4,0) -> 성취도 5단계+석차등급O
B24: 과학 | C24: =VLOOKUP(D24,숨김!$B$3:$E$300,2,0) -> 공통 | D24: 통합과학1 | E24: =VLOOKUP(D24,숨김!$B$3:$E$300,3,0) -> 4 | F24: 4 | G24: 4 | M24: =SUM(G24:L27) -> 10 | O24: =VLOOKUP(D24,숨김!$B$3:$E$300,4,0) -> 성취도 5단계+석차등급O
C25: =VLOOKUP(D25,숨김!$B$3:$E$300,2,0) -> 공통 | D25: 통합과학2 | E25: =VLOOKUP(D25,숨김!$B$3:$E$300,3,0) -> 4 | F25: 4 | H25: 4 | O25: =VLOOKUP(D25,숨김!$B$3:$E$300,4,0) -> 성취도 5단계+석차등급O
C26: =VLOOKUP(D26,숨김!$B$3:$E$300,2,0) -> 공통 | D26: 과학탐구실험1 | E26: =VLOOKUP(D26,숨김!$B$3:$E$300,3,0) -> 1 | F26: 1 | G26: 1 | O26: =VLOOKUP(D26,숨김!$B$3:$E$300,4,0) -> 성취도 3단계
C27: =VLOOKUP(D27,숨김!$B$3:$E$300,2,0) -> 공통 | D27: 과학탐구실험2 | E27: =VLOOKUP(D27,숨김!$B$3:$E$300,3,0) -> 1 | F27: 1 | H27: 1 | O27: =VLOOKUP(D27,숨김!$B$3:$E$300,4,0) -> 성취도 3단계
B28: 체육 | C28: =VLOOKUP(D28,숨김!$B$3:$E$300,2,0) -> 일반 | D28: 체육1 | E28: =VLOOKUP(D28,숨김!$B$3:$E$300,3,0) -> 3 | F28: 2 | G28: 2 | M28: =SUM(G28:L33) -> 10 | O28: =VLOOKUP(D28,숨김!$B$3:$E$300,4,0) -> 성취도 3단계
C29: =VLOOKUP(D29,숨김!$B$3:$E$300,2,0) -> 일반 | D29: 체육2 | E29: =VLOOKUP(D29,숨김!$B$3:$E$300,3,0) -> 3 | F29: 2 | H29: 2 | O29: =VLOOKUP(D29,숨김!$B$3:$E$300,4,0) -> 성취도 3단계
C30: =VLOOKUP(D30,숨김!$B$3:$E$300,2,0) -> 진로 | D30: 스포츠 과학 | E30: =VLOOKUP(D30,숨김!$B$3:$E$300,3,0) -> 2 | F30: 1 | I30: 1 | O30: =VLOOKUP(D30,숨김!$B$3:$E$300,4,0) -> 성취도 3단계
C31: =VLOOKUP(D31,숨김!$B$3:$E$300,2,0) -> 진로 | D31: 스포츠 문화 | E31: =VLOOKUP(D31,숨김!$B$3:$E$300,3,0) -> 2 | F31: 1 | J31: 1 | O31: =VLOOKUP(D31,숨김!$B$3:$E$300,4,0) -> 성취도 3단계
C32: =VLOOKUP(D32,숨김!$B$3:$E$300,2,0) -> 융합 | D32: 스포츠 생활1 | E32: =VLOOKUP(D32,숨김!$B$3:$E$300,3,0) -> 3 | F32: 2 | K32: 2 | O32: =VLOOKUP(D32,숨김!$B$3:$E$300,4,0) -> 성취도 3단계
C33: =VLOOKUP(D33,숨김!$B$3:$E$300,2,0) -> 융합 | D33: 스포츠 생활2 | E33: =VLOOKUP(D33,숨김!$B$3:$E$300,3,0) -> 3 | F33: 2 | L33: 2 | O33: =VLOOKUP(D33,숨김!$B$3:$E$300,4,0) -> 성취도 3단계
B34: 예술 | C34: 일반 | D34: 음악↔미술 | E34: 3 | F34: 2↔2 | I34: 2 | J34: 2 | M34: =SUM(G34:L34) -> 4 | O34: 성취도 3단계
B35: 기술·가정 | C35: 일반 | D35: 기술·가정↔정보 | E35: 4 | F35: 3↔3 | G35: 3 | H35: 3 | M35: 6 | O35: 성취도 5단계+석차등급O
B36: 정보 | C36: 일반
A37: 학교 지정 과목 교과 이수 학점 소계 | G37: =SUM(G5:G36) -> 29 | H37: =SUM(H5:H36) -> 29 | I37: =SUM(I5:I36) -> 15 | J37: =SUM(J5:J36) -> 15 | K37: =SUM(K5:K36) -> 14 | L37: =SUM(L5:L36) -> 2 | M37: =SUM(G37:L37) -> 104
A38: 선택군A | B38: 사회 | C38: =VLOOKUP(D38,숨김!$B$3:$E$300,2,0) -> 일반 | D38: 사회와 문화 | E38: =VLOOKUP(D38,숨김!$B$3:$E$300,3,0) -> 4 | F38: 4 | I38: 4 | M38: =SUM(G38:L46) -> 12 | O38: =VLOOKUP(D38,숨김!$B$3:$E$300,4,0) -> 성취도 5단계+석차등급O
C39: =VLOOKUP(D39,숨김!$B$3:$E$300,2,0) -> 일반 | D39: 세계시민과 지리 | E39: =VLOOKUP(D39,숨김!$B$3:$E$300,3,0) -> 4 | F39: 4 | I39: 4 | O39: =VLOOKUP(D39,숨김!$B$3:$E$300,4,0) -> 성취도 5단계+석차등급O
C40: =VLOOKUP(D40,숨김!$B$3:$E$300,2,0) -> 진로 | D40: 동아시아 역사 기행 | E40: =VLOOKUP(D40,숨김!$B$3:$E$300,3,0) -> 4 | F40: 4 | I40: 4 | O40: =VLOOKUP(D40,숨김!$B$3:$E$300,4,0) -> 성취도 5단계+석차등급O
...

Sheet 2025 입학생 3개년(2학년)
A1: 2025학년도 입학생 3개년 교육과정 편성표(2학년) | Q1: Ⅰ | R1: Ⅱ
A2: 웅상고등학교(공립)
A3: 구분 | B3: 교과(군) | C3: 과목 유형 | D3: 과목 | E3: 기본 학점 | F3: 운영 학점 | G3: 1학년 | I3: 2학년 | K3: 3학년 | M3: 편성학점 합 | O3: 성적처리 유형
G4: 1학기 | H4: 2학기 | I4: 1학기 | J4: 2학기 | K4: 1학기 | L4: 2학기 | M4: 교과(군) | N4: 선택군
A5: 학 교 지 정 과 목 | B5: 국어 | C5: =VLOOKUP(D5,숨김!$B$3:$E$300,2,0) -> 공통 | D5: 공통국어1 | E5: =VLOOKUP(D5,숨김!$B$3:$E$300,3,0) -> 4 | F5: 4 | G5: 4 | M5: =SUM(G5:L9) -> 20 | N5: =SUM(M5,M10,M15) -> 60 | O5: =VLOOKUP(D5,숨김!$B$3:$E$300,4,0) -> 성취도 5단계+석차등급O
C6: =VLOOKUP(D6,숨김!$B$3:$E$300,2,0) -> 공통 | D6: 공통국어2 | E6: =VLOOKUP(D6,숨김!$B$3:$E$300,3,0) -> 4 | F6: 4 | H6: 4 | O6: =VLOOKUP(D6,숨김!$B$3:$E$300,4,0) -> 성취도 5단계+석차등급O
C7: =VLOOKUP(D7,숨김!$B$3:$E$300,2,0) -> 일반 | D7: 독서와 작문 | E7: =VLOOKUP(D7,숨김!$B$3:$E$300,3,0) -> 4 | F7: 4 | I7: 4 | O7: =VLOOKUP(D7,숨김!$B$3:$E$300,4,0) -> 성취도 5단계+석차등급O
C8: =VLOOKUP(D8,숨김!$B$3:$E$300,2,0) -> 일반 | D8: 문학 | E8: =VLOOKUP(D8,숨김!$B$3:$E$300,3,0) -> 4 | F8: 4 | J8: 4 | O8: =VLOOKUP(D8,숨김!$B$3:$E$300,4,0) -> 성취도 5단계+석차등급O
C9: =VLOOKUP(D9,숨김!$B$3:$E$300,2,0) -> 일반 | D9: 화법과 언어 | E9: =VLOOKUP(D9,숨김!$B$3:$E$300,3,0) -> 4 | F9: 4 | K9: 4 | O9: =VLOOKUP(D9,숨김!$B$3:$E$300,4,0) -> 성취도 5단계+석차등급O
B10: 수학 | C10: =VLOOKUP(D10,숨김!$B$3:$E$300,2,0) -> 공통 | D10: 공통수학1 | E10: =VLOOKUP(D10,숨김!$B$3:$E$300,3,0) -> 4 | F10: 4 | G10: 4 | M10: =SUM(G10:L14) -> 20 | O10: =VLOOKUP(D10,숨김!$B$3:$E$300,4,0) -> 성취도 5단계+석차등급O
C11: =VLOOKUP(D11,숨김!$B$3:$E$300,2,0) -> 공통 | D11: 공통수학2 | E11: =VLOOKUP(D11,숨김!$B$3:$E$300,3,0) -> 4 | F11: 4 | H11: 4 | O11: =VLOOKUP(D11,숨김!$B$3:$E$300,4,0) -> 성취도 5단계+석차등급O
C12: =VLOOKUP(D12,숨김!$B$3:$E$300,2,0) -> 일반 | D12: 대수 | E12: =VLOOKUP(D12,숨김!$B$3:$E$300,3,0) -> 4 | F12: 4 | I12: 4 | O12: =VLOOKUP(D12,숨김!$B$3:$E$300,4,0) -> 성취도 5단계+석차등급O
C13: =VLOOKUP(D13,숨김!$B$3:$E$300,2,0) -> 일반 | D13: 미적분Ⅰ | E13: =VLOOKUP(D13,숨김!$B$3:$E$300,3,0) -> 4 | F13: 4 | J13: 4 | O13: =VLOOKUP(D13,숨김!$B$3:$E$300,4,0) -> 성취도 5단계+석차등급O
C14: =VLOOKUP(D14,숨김!$B$3:$E$300,2,0) -> 일반 | D14: 확률과 통계 | E14: =VLOOKUP(D14,숨김!$B$3:$E$300,3,0) -> 4 | F14: 4 | K14: 4 | O14: =VLOOKUP(D14,숨김!$B$3:$E$300,4,0) -> 성취도 5단계+석차등급O
B15: 영어 | C15: =VLOOKUP(D15,숨김!$B$3:$E$300,2,0) -> 공통 | D15: 공통영어1 | E15: =VLOOKUP(D15,숨김!$B$3:$E$300,3,0) -> 4 | F15: 4 | G15: 4 | M15: =SUM(G15:L19) -> 20 | O15: =VLOOKUP(D15,숨김!$B$3:$E$300,4,0) -> 성취도 5단계+석차등급O
C16: =VLOOKUP(D16,숨김!$B$3:$E$300,2,0) -> 공통 | D16: 공통영어2 | E16: =VLOOKUP(D16,숨김!$B$3:$E$300,3,0) -> 4 | F16: 4 | H16: 4 | O16: =VLOOKUP(D16,숨김!$B$3:$E$300,4,0) -> 성취도 5단계+석차등급O
C17: =VLOOKUP(D17,숨김!$B$3:$E$300,2,0) -> 일반 | D17: 영어Ⅰ | E17: =VLOOKUP(D17,숨김!$B$3:$E$300,3,0) -> 4 | F17: 4 | I17: 4 | O17: =VLOOKUP(D17,숨김!$B$3:$E$300,4,0) -> 성취도 5단계+석차등급O
C18: =VLOOKUP(D18,숨김!$B$3:$E$300,2,0) -> 일반 | D18: 영어Ⅱ | E18: =VLOOKUP(D18,숨김!$B$3:$E$300,3,0) -> 4 | F18: 4 | J18: 4 | O18: =VLOOKUP(D18,숨김!$B$3:$E$300,4,0) -> 성취도 5단계+석차등급O
C19: =VLOOKUP(D19,숨김!$B$3:$E$300,2,0) -> 일반 | D19: 영어 독해와 작문 | E19: =VLOOKUP(D19,숨김!$B$3:$E$300,3,0) -> 4 | F19: 4 | K19: 4 | O19: =VLOOKUP(D19,숨김!$B$3:$E$300,4,0) -> 성취도 5단계+석차등급O
B20: 사회 | C20: =VLOOKUP(D20,숨김!$B$3:$E$300,2,0) -> 공통 | D20: 한국사1 | E20: =VLOOKUP(D20,숨김!$B$3:$E$300,3,0) -> 3 | F20: 3 | G20: 3 | M20: =SUM(G20:L21) -> 6 | O20: =VLOOKUP(D20,숨김!$B$3:$E$300,4,0) -> 성취도 5단계+석차등급O
C21: =VLOOKUP(D21,숨김!$B$3:$E$300,2,0) -> 공통 | D21: 한국사2 | E21: =VLOOKUP(D21,숨김!$B$3:$E$300,3,0) -> 3 | F21: 3 | H21: 3 | O21: =VLOOKUP(D21,숨김!$B$3:$E$300,4,0) -> 성취도 5단계+석차등급O
C22: =VLOOKUP(D22,숨김!$B$3:$E$300,2,0) -> 공통 | D22: 통합사회1 | E22: =VLOOKUP(D22,숨김!$B$3:$E$300,3,0) -> 4 | F22: 4 | G22: 4 | M22: =SUM(G22:L23) -> 8 | O22: =VLOOKUP(D22,숨김!$B$3:$E$300,4,0) -> 성취도 5단계+석차등급O
C23: =VLOOKUP(D23,숨김!$B$3:$E$300,2,0) -> 공통 | D23: 통합사회2 | E23: =VLOOKUP(D23,숨김!$B$3:$E$300,3,0) -> 4 | F23: 4 | H23: 4 | O23: =VLOOKUP(D23,숨김!$B$3:$E$300,4,0) -> 성취도 5단계+석차등급O
B24: 과학 | C24: =VLOOKUP(D24,숨김!$B$3:$E$300,2,0) -> 공통 | D24: 통합과학1 | E24: =VLOOKUP(D24,숨김!$B$3:$E$300,3,0) -> 4 | F24: 4 | G24: 4 | M24: =SUM(G24:L27) -> 10 | O24: =VLOOKUP(D24,숨김!$B$3:$E$300,4,0) -> 성취도 5단계+석차등급O
C25: =VLOOKUP(D25,숨김!$B$3:$E$300,2,0) -> 공통 | D25: 통합과학2 | E25: =VLOOKUP(D25,숨김!$B$3:$E$300,3,0) -> 4 | F25: 4 | H25: 4 | O25: =VLOOKUP(D25,숨김!$B$3:$E$300,4,0) -> 성취도 5단계+석차등급O
C26: =VLOOKUP(D26,숨김!$B$3:$E$300,2,0) -> 공통 | D26: 과학탐구실험1 | E26: =VLOOKUP(D26,숨김!$B$3:$E$300,3,0) -> 1 | F26: 1 | G26: 1 | O26: =VLOOKUP(D26,숨김!$B$3:$E$300,4,0) -> 성취도 3단계
C27: =VLOOKUP(D27,숨김!$B$3:$E$300,2,0) -> 공통 | D27: 과학탐구실험2 | E27: =VLOOKUP(D27,숨김!$B$3:$E$300,3,0) -> 1 | F27: 1 | H27: 1 | O27: =VLOOKUP(D27,숨김!$B$3:$E$300,4,0) -> 성취도 3단계
B28: 체육 | C28: =VLOOKUP(D28,숨김!$B$3:$E$300,2,0) -> 일반 | D28: 체육1 | E28: =VLOOKUP(D28,숨김!$B$3:$E$300,3,0) -> 3 | F28: 2 | G28: 2 | M28: =SUM(G28:L33) -> 10 | O28: =VLOOKUP(D28,숨김!$B$3:$E$300,4,0) -> 성취도 3단계
C29: =VLOOKUP(D29,숨김!$B$3:$E$300,2,0) -> 일반 | D29: 체육2 | E29: =VLOOKUP(D29,숨김!$B$3:$E$300,3,0) -> 3 | F29: 2 | H29: 2 | O29: =VLOOKUP(D29,숨김!$B$3:$E$300,4,0) -> 성취도 3단계
C30: =VLOOKUP(D30,숨김!$B$3:$E$300,2,0) -> 진로 | D30: 스포츠 과학 | E30: =VLOOKUP(D30,숨김!$B$3:$E$300,3,0) -> 2 | F30: 1 | I30: 1 | O30: =VLOOKUP(D30,숨김!$B$3:$E$300,4,0) -> 성취도 3단계
C31: =VLOOKUP(D31,숨김!$B$3:$E$300,2,0) -> 진로 | D31: 스포츠 문화 | E31: =VLOOKUP(D31,숨김!$B$3:$E$300,3,0) -> 2 | F31: 1 | J31: 1 | O31: =VLOOKUP(D31,숨김!$B$3:$E$300,4,0) -> 성취도 3단계
C32: =VLOOKUP(D32,숨김!$B$3:$E$300,2,0) -> 융합 | D32: 스포츠 생활1 | E32: =VLOOKUP(D32,숨김!$B$3:$E$300,3,0) -> 3 | F32: 2 | K32: 2 | O32: =VLOOKUP(D32,숨김!$B$3:$E$300,4,0) -> 성취도 3단계
C33: =VLOOKUP(D33,숨김!$B$3:$E$300,2,0) -> 융합 | D33: 스포츠 생활2 | E33: =VLOOKUP(D33,숨김!$B$3:$E$300,3,0) -> 3 | F33: 2 | L33: 2 | O33: =VLOOKUP(D33,숨김!$B$3:$E$300,4,0) -> 성취도 3단계
B34: 예술 | C34: 일반 | D34: 음악↔미술 | E34: 3 | F34: 2↔2 | I34: 2 | J34: 2 | M34: =SUM(G34:L34) -> 4 | O34: 성취도 3단계
B35: 기술·가정 | C35: 일반 | D35: 기술·가정↔정보 | E35: 4 | F35: 3↔3 | G35: 3 | H35: 3 | M35: 6 | O35: 성취도 5단계+석차등급O
B36: 정보 | C36: 일반
A37: 학교 지정 과목 교과 이수 학점 소계 | G37: =SUM(G5:G36) -> 29 | H37: =SUM(H5:H36) -> 29 | I37: =SUM(I5:I36) -> 15 | J37: =SUM(J5:J36) -> 15 | K37: =SUM(K5:K36) -> 14 | L37: =SUM(L5:L36) -> 2 | M37: =SUM(G37:L37) -> 104
A38: 선택군A | B38: 사회 | C38: =VLOOKUP(D38,숨김!$B$3:$E$300,2,0) -> 진로 | D38: 윤리와 사상 | E38: =VLOOKUP(D38,숨김!$B$3:$E$300,3,0) -> 4 | F38: 4 | I38: 4 | M38: =SUM(G38:L46) -> 12 | O38: =VLOOKUP(D38,숨김!$B$3:$E$300,4,0) -> 성취도 5단계+석차등급O
C39: =VLOOKUP(D39,숨김!$B$3:$E$300,2,0) -> 일반 | D39: 사회와 문화 | E39: =VLOOKUP(D39,숨김!$B$3:$E$300,3,0) -> 4 | F39: 4 | I39: 4 | O39: =VLOOKUP(D39,숨김!$B$3:$E$300,4,0) -> 성취도 5단계+석차등급O
C40: =VLOOKUP(D40,숨김!$B$3:$E$300,2,0) -> 진로 | D40: 동아시아 역사 기행 | E40: =VLOOKUP(D40,숨김!$B$3:$E$300,3,0) -> 4 | F40: 4 | I40: 4 | O40: =VLOOKUP(D40,숨김!$B$3:$E$300,4,0) -> 성취도 5단계+석차등급O
...

Sheet 2024 입학생 3개년(3학년)
A1: 2024학년도 입학생 3개년 교육과정 편성표(3학년)
A2: 웅상 고등학교(공립)
A3: 구 분 | B3: 교과 영역 | C3: 교과(군) | D3: 과목 유형 | E3: 과목 | F3: 기본 학점 | G3: 운영 학점 | H3: 1학년 | J3: 2학년 | L3: 3학년 | N3: 편성학점 합 | P3: 성적처리 유형
H4: 1학기 | I4: 2학기 | J4: 1학기 | K4: 2학기 | L4: 1학기 | M4: 2학기 | N4: 교과군 | O4: 교과영역
A5: 학 교 지 정 과 목 | B5: 기초 | C5: 국어 | D5: 공통 | E5: 국어 | F5: 8 | G5: 8 | H5: 4 | I5: 4 | N5: =SUM(H5:M7) -> 16 | O5: =SUM(N5:N15) -> 58 | P5: 성취도 5단계+석차등급O
D6: 일반 | E6: 문학 | F6: 5 | G6: 4 | J6: 4 | P6: 성취도 5단계+석차등급O
D7: 일반 | E7: 독서 | F7: 5 | G7: 4 | K7: 4 | P7: 성취도 5단계+석차등급O
C8: 수학 | D8: 공통 | E8: 수학 | F8: 8 | G8: 8 | H8: 4 | I8: 4 | N8: =SUM(H8:M11) -> 20 | P8: 성취도 5단계+석차등급O
D9: 일반 | E9: 수학Ⅰ | F9: 5 | G9: 4 | J9: 4 | P9: 성취도 5단계+석차등급O
D10: 일반 | E10: 수학Ⅱ | F10: 5 | G10: 4 | K10: 4 | P10: 성취도 5단계+석차등급O
D11: 일반 | E11: 확률과통계 | F11: 5 | G11: 4 | J11: 2 | K11: 2 | P11: 성취도 5단계+석차등급O
C12: 영어 | D12: 공통 | E12: 영어 | F12: 8 | G12: 8 | H12: 4 | I12: 4 | N12: =SUM(H12:M14) -> 16 | P12: 성취도 5단계+석차등급O
D13: 일반 | E13: 영어Ⅰ | F13: 5 | G13: 4 | J13: 4 | P13: 성취도 5단계+석차등급O
D14: 일반 | E14: 영어Ⅱ | F14: 5 | G14: 4 | K14: 4 | P14: 성취도 5단계+석차등급O
C15: 한국사 | D15: 공통 | E15: 한국사 | F15: 6 | G15: 6 | H15: 3 | I15: 3 | N15: =SUM(H15:M15) -> 6 | P15: 성취도 5단계+석차등급O
B16: 탐구 | C16: 사회 | D16: 공통 | E16: 공통사회 | F16: 8 | G16: 6 | H16: 3 | I16: 3 | N16: =SUM(H16:M16) -> 6 | O16: =SUM(N16:N18) -> 14 | P16: 성취도 5단계+석차등급O
C17: 과학 | D17: 공통 | E17: 공통과학 | F17: 8 | G17: 6 | H17: 3 | I17: 3 | N17: =SUM(H17:M18) -> 8 | P17: 성취도 5단계+석차등급O
D18: 공통 | E18: 과학탐구실험 | F18: 2 | G18: 2 | H18: 1 | I18: 1 | P18: 성취도 3단계
B19: 체육 · 예술 | C19: 체육 | D19: 일반 | E19: 체육 | F19: 5 | G19: 6 | H19: 1 | I19: 1 | J19: 2 | K19: 2 | N19: =SUM(H19:M20) -> 10 | O19: =SUM(N19:N23) -> 20 | P19: 성취도 3단계
D20: 일반 | E20: 운동과건강 | F20: 5 | G20: 4 | L20: 2 | M20: 2 | P20: 성취도 3단계
C21: 예술 | D21: 일반 | E21: 미술 | F21: 5 | G21: 4 | H21: 2 | I21: 2 | N21: =SUM(H21:M23) -> 10 | P21: 성취도 3단계
D22: 진로 | E22: 미술창작 | F22: 5 | G22: 2 | J22: 1 | K22: 1 | P22: 성취도 3단계+성취도별 분포비율
D23: 일반 | E23: 음악 | F23: 5 | G23: 4 | J23: 2 | K23: 2 | P23: 성취도 3단계
B24: 생활 · 교양 | C24: 기술·가정 | D24: 일반 | E24: 기술가정 | F24: 5 | G24: 4 | H24: 2 | I24: 2 | N24: =SUM(H24:M25) -> 8 | O24: =SUM(N24:N25) -> 8 | P24: 성취도 5단계+석차등급O
D25: 일반 | E25: 정보 | F25: 5 | G25: 4 | H25: 2 | I25: 2 | P25: 성취도 5단계+석차등급O
A26: 학교 지정 과목 교과 이수 학점 소계 | H26: =SUM(H5:H25) -> 29 | I26: =SUM(I5:I25) -> 29 | J26: =SUM(J5:J25) -> 19 | K26: =SUM(K5:K25) -> 19 | L26: =SUM(L5:L25) -> 2 | M26: =SUM(M5:M25) -> 2 | O26: =SUM(O5:O25) -> 100
A27: 학 생 선 택 과 목 | B27: 선 택 군 A | C27: 사회 | D27: 일반 | E27: 세계지리 | F27: 5 | G27: 4 | J27: 4 | K27: 4 | N27: =SUM(H27:M33) -> 16 | O27: =SUM(N27:N27) -> 16 | P27: 성취도 5단계+석차등급O
D28: 일반 | E28: 생활과윤리 | F28: 5 | G28: 4 | J28: 4 | K28: 4 | P28: 성취도 5단계+석차등급O
D29: 일반 | E29: 정치와법 | F29: 5 | G29: 4 | P29: 성취도 5단계+석차등급O
D30: 일반 | E30: 세계사 | F30: 5 | G30: 4 | P30: 성취도 5단계+석차등급O
C31: 과학 | D31: 일반 | E31: 물리학Ⅰ | F31: 5 | G31: 4 | P31: 성취도 5단계+석차등급O
D32: 일반 | E32: 화학Ⅰ | F32: 5 | G32: 4 | P32: 성취도 5단계+석차등급O
D33: 일반 | E33: 생명과학Ⅰ | F33: 5 | G33: 4 | P33: 성취도 5단계+석차등급O
D34: 일반 | E34: 지구과학Ⅰ | F34: 5 | G34: 4 | P34: 성취도 5단계+석차등급O
B35: 선 택 군 B | C35: 제2외국어 | D35: 일반 | E35: 일본어Ⅰ | F35: 5 | G35: 4 | J35: 2 | K35: 2 | N35: =SUM(H35:M36) -> 4 | O35: =SUM(I35:M36) -> 4 | P35: 성취도 5단계+석차등급O
D36: 일반 | E36: 중국어Ⅰ | F36: 5 | G36: 4 | P36: 성취도 5단계+석차등급O
B37: 선 택 군 C | C37: 국어 | D37: 일반 | E37: 화법과작문 | F37: 5 | G37: 6 | L37: 3 | M37: 3 | N37: =SUM(H37:M44) -> 24 | O37: =SUM(I37:M44) -> 24 | P37: 성취도 5단계+석차등급O
D38: 일반 | E38: 언어와매체 | F38: 5 | G38: 6 | L38: 3 | M38: 3 | P38: 성취도 5단계+석차등급O
D39: 진로 | E39: 심화국어 | F39: 5 | G39: 6 | L39: 3 | M39: 3 | P39: 성취도 3단계+성취도별 분포비율
C40: 수학 | D40: 일반 | E40: 미적분 | F40: 5 | G40: 6 | L40: 3 | M40: 3 | P40: 성취도 5단계+석차등급O
...

Sheet 숨김
B1: =SUBTOTAL(3,B3:B298) -> 290
B2: 과목명 | C2: 유형 | D2: 기본학점 | E2: 성적 처리 유형 | F2: 편성 최소 학점 | G2: 편성 최대 학점 | H2: 편성 학점 범위
B3: 공통국어1 | C3: 공통 | D3: 4 | E3: 성취도 5단계+석차등급O | F3: 3 | G3: 4 | H3: 3~4
B4: 공통국어2 | C4: 공통 | D4: 4 | E4: 성취도 5단계+석차등급O | F4: 3 | G4: 4 | H4: 3~4
B5: 화법과 언어 | C5: 일반 | D5: 4 | E5: 성취도 5단계+석차등급O | F5: 3 | G5: 5 | H5: 3~5
B6: 독서와 작문 | C6: 일반 | D6: 4 | E6: 성취도 5단계+석차등급O | F6: 3 | G6: 5 | H6: 3~5
B7: 문학 | C7: 일반 | D7: 4 | E7: 성취도 5단계+석차등급O | F7: 3 | G7: 5 | H7: 3~5
B8: 주제 탐구 독서 | C8: 진로 | D8: 4 | E8: 성취도 5단계+석차등급O | F8: 3 | G8: 5 | H8: 3~5
B9: 문학과 영상 | C9: 진로 | D9: 4 | E9: 성취도 5단계+석차등급O | F9: 3 | G9: 5 | H9: 3~5
B10: 직무 의사소통 | C10: 진로 | D10: 4 | E10: 성취도 5단계+석차등급O | F10: 3 | G10: 5 | H10: 3~5
B11: 독서 토론과 글쓰기 | C11: 융합 | D11: 4 | E11: 성취도 5단계+석차등급O | F11: 3 | G11: 5 | H11: 3~5
B12: 매체 의사소통 | C12: 융합 | D12: 4 | E12: 성취도 5단계+석차등급O | F12: 3 | G12: 5 | H12: 3~5
B13: 언어생활 탐구 | C13: 융합 | D13: 4 | E13: 성취도 5단계+석차등급O | F13: 3 | G13: 5 | H13: 3~5
B14: 공통수학1 | C14: 공통 | D14: 4 | E14: 성취도 5단계+석차등급O | F14: 3 | G14: 4 | H14: 3~4
... B43: 세계 문화와 영어 | C43: 융합 | D43: 4 | E43: 성취도 5단계+석차등급O | F43: 3 | G43: 5 | H43: 3~5
B44: 한국사1 | C44: 공통 | D44: 3 | E44: 성취도 5단계+석차등급O | F44: 3 | G44: 3 | H44: 3
B45: 한국사2 | C45: 공통 | D45: 3 | E45: 성취도 5단계+석차등급O | F45: 3 | G45: 3 | H45: 3
B46: 통합사회1 | C46: 공통 | D46: 4 | E46: 성취도 5단계+석차등급O | F46: 3 | G46: 4 | H46: 3~4
B47: 통합사회2 | C47: 공통 | D47: 4 | E47: 성취도 5단계+석차등급O | F47: 3 | G47: 4 | H47: 3~4
B48: 세계시민과 지리 | C48: 일반 | D48: 4 | E48: 성취도 5단계+석차등급O | F48: 3 | G48: 5 | H48: 3~5
B49: 세계사 | C49: 일반 | D49: 4 | E49: 성취도 5단계+석차등급O | F49: 3 | G49: 5 | H49: 3~5
B50: 사회와 문화 | C50: 일반 | D50: 4 | E50: 성취도 5단계+석차등급O | F50: 3 | G50: 5 | H50: 3~5
B51: 현대사회와 윤리 | C51: 일반 | D51: 4 | E51: 성취도 5단계+석차등급O | F51: 3 | G51: 5 | H51: 3~5
B52: 한국지리 탐구 | C52: 진로 | D52: 4 | E52: 성취도 5단계+석차등급O | F52: 3 | G52: 5 | H52: 3~5
B53: 도시의 미래 탐구 | C53: 진로 | D53: 4 | E53: 성취도 5단계+석차등급O | F53: 3 | G53: 5 | H53: 3~5
B54: 동아시아 역사 기행 | C54: 진로 | D54: 4 | E54: 성취도 5단계+석차등급O | F54: 3 | G54: 5 | H54: 3~5
B55: 정치 | C55: 진로 | D55: 4 | E55: 성취도 5단계+석차등급O | F55: 3 | G55: 5 | H55: 3~5
B56: 법과 사회 | C56: 진로 | D56: 4 | E56: 성취도 5단계+석차등급O | F56: 3 | G56: 5 | H56: 3~5
B57: 경제 | C57: 진로 | D57: 4 | E57: 성취도 5단계+석차등급O | F57: 3 | G57: 5 | H57: 3~5
... B68: 통합과학2 | C68: 공통 | D68: 4 | E68: 성취도 5단계+석차등급O | F68: 3 | G68: 4 | H68: 3~4
B69: 과학탐구실험1 | C69: 공통 | D69: 1 | E69: 성취도 3단계 | F69: 1 | G69: 1 | H69: 1
B70: 과학탐구실험2 | C70: 공통 | D70: 1 | E70: 성취도 3단계 | F70: 1 | G70: 1 | H70: 1
B71: 물리학 | C71: 일반 | D71: 4 | E71: 성취도 5단계+석차등급O | F71: 3 | G71: 5 | H71: 3~5
B72: 화학 | C72: 일반 | D72: 4 | E72: 성취도 5단계+석차등급O | F72: 3 | G72: 5 | H72: 3~5
B73: 생명과학 | C73: 일반 | D73: 4 | E73: 성취도 5단계+석차등급O | F73: 3 | G73: 5 | H73: 3~5
B74: 지구과학 | C74: 일반 | D74: 4 | E74: 성취도 5단계+석차등급O | F74: 3 | G74: 5 | H74: 3~5
B75: 역학과 에너지 | C75: 진로 | D75: 4 | E75: 성취도 5단계+석차등급O | F75: 3 | G75: 5 | H75: 3~5
B76: 전자기와 양자 | C76: 진로 | D76: 4 | E76: 성취도 5단계+석차등급O | F76: 3 | G76: 5 | H76: 3~5
B77: 물질과 에너지 | C77: 진로 | D77: 4 | E77: 성취도 5단계+석차등급O | F77: 3 | G77: 5 | H77: 3~5
B78: 화학 반응의 세계 | C78: 진로 | D78: 4 | E78: 성취도 5단계+석차등급O | F78: 3 | G78: 5 | H78: 3~5
...
